<?xml version="1.0" ?>
<!-- =================================================================================== -->
<!-- |    This document was autogenerated by xacro from spirit40_ros2.urdf.xacro       | -->
<!-- |    EDITING THIS FILE BY HAND IS NOT RECOMMENDED                                 | -->
<!-- =================================================================================== -->
<robot xmlns:xacro="http://www.ros.org/wiki/xacro" name="spirit">
  <!-- Define parameters -->
  <!-- bodyLength + hipdx should be equal to front to back hip distance -->
  <!-- dy +  dPodAxisToEdge + upperLegWidth should be equal to the center to toe distance along y axis-->
  <!-- guess -->
  <!-- guess -->
  <!-- guess -->
  <!-- guess -->
  <!-- guess -->
  <!-- guess -->
  <!--visual only-->
  <!--center of pod cylinder to the ab axis-->
  <!-- originally 100 -->
  <!-- originally 50 -->
  <!-- Define materials -->
  <material name="darkgray">
    <color rgba="0.1 0.1 0.1 1.0"/>
  </material>
  <material name="silver">
    <color rgba="0.3 0.3 0.3 1.0"/>
  </material>
  <material name="red">
    <color rgba="0.8 0.0 0.2 1.0"/>
  </material>
  <!-- Body -->
  <link name="body">
    <!-- <visual>
			<origin rpy="0 0 0" xyz="0 0 0"/>
			<geometry>
				<box size="${bodyLength} ${bodyWidth} ${bodyHeight}"/>
			</geometry>
			<material name="darkgray"/>
		</visual> -->
    <visual>
      <origin rpy="0 0 0" xyz="0.03 0 0"/>
      <geometry>
        <mesh filename="meshes/Spirit40_Body_Mesh_transformed.stl" scale="1 1 1"/>
      </geometry>
      <material name="darkgray"/>
    </visual>
    <inertial>
      <mass value="5.75"/>
      <!-- Uniform box -->
      <!-- <inertia ixx="1/12*${bodyMass}*(${bodyWidth}*${bodyWidth} + ${bodyHeight}*${bodyHeight})"  ixy="0"  ixz="0" iyy="1/12*${bodyMass}*(${bodyLength}*${bodyLength} + ${bodyHeight}*${bodyHeight})" iyz="0" izz="1/12*${bodyMass}*(${bodyLength}*${bodyLength} + ${bodyWidth}*${bodyWidth})"/> -->
      <inertia ixx="0.05" ixy="0" ixz="0" iyy="0.1" iyz="0" izz="0.1"/>
      <!-- Training Wheels: No Rotation -->
      <!-- <inertia ixx="1000"  ixy="0"  ixz="0" iyy="100000" iyz="0" izz="1000" /> -->
      <!-- Training Wheels: Sagittal Rotation Only -->
      <!-- <inertia ixx="1000"  ixy="0"  ixz="0" iyy="0.1" iyz="0" izz="1000" /> -->
    </inertial>
    <!-- Just copy geometry for collision -->
    <collision>
      <origin rpy="0 0 0" xyz="0 0 0"/>
      <geometry>
        <box size="0.335 0.24 0.104"/>
      </geometry>
    </collision>
  </link>
 
  <link name="base_link"/>
  <joint name="base_link_to_body" type="fixed">
    <parent link="base_link"/>
    <child link="body"/>
    <origin xyz="0.0 0.0 0.0" rpy="0 0 0"/>
    <axis xyz="1 0 0"/>
  </joint>


  <!-- Define our leg macro -->
  <!-- Our four legs -->

  
  <link name="hip0">
    <visual>
      <!-- <origin rpy="${pi/2} 0 0" xyz="${front * 0} ${left * (dPodAxisToEdge)} 0"/> -->
      <!-- <geometry>
					<cylinder length="${podLength}" radius="${podRadius}"/>
				</geometry> -->
      <!-- <material name="${color}"/>
			</visual>
			<visual> -->
      <geometry>
        <mesh filename="meshes/Spirit40_Hip_Module_transformed.stl" scale="1 1 1"/>
      </geometry>
      <xacro:if value="1">
        <origin rpy="0 0 0" xyz="0 0.0 0"/>
      </xacro:if>
      <xacro:if value="1">
        <origin rpy="0 3.14159265359 0" xyz="0.0 0.0 0"/>
      </xacro:if>
      <xacro:if value="1">
        <origin rpy="3.14159265359 0 0" xyz="0.0 0 0.0"/>
      </xacro:if>
      <xacro:if value="1">
        <origin rpy="3.14159265359 3.14159265359 0" xyz="0.0 0.0 0.0"/>
      </xacro:if>
      <!-- <geometry>
					<mesh filename="file://$(arg mesh_dir)/Spirit40/Spirit40_Hip_Module_transformed.stl"
						  scale="1 1 1"/>
				</geometry> -->
      <material name="darkgray"/>
    </visual>
    <collision>
      <origin rpy="1.570796326795 0 0" xyz="0 0.028 0"/>
      <geometry>
        <cylinder length="0.08" radius="0.055"/>
      </geometry>
    </collision>
    <inertial>
      <mass value="0.575"/>
      <!-- <inertia ixx="1/12*${podMass}*${podLength}*${podLength} + 1/4*${podMass}*${podRadius}*${podRadius}"  ixy="0"  ixz="0" iyy="1/12*${podMass}*${podLength}*${podLength} + 1/4*${podMass}*${podRadius}*${podRadius}" iyz="0" izz="1/2*${podMass}*${podRadius}*$
				{podRadius}" /> -->
      <inertia ixx="0.00066963541" ixy="0" ixz="0" iyy="0.00066963541" iyz="0" izz="0.0008696875"/>
    </inertial>
  </link>

  <joint name="8" type="revolute">
    <parent link="body"/>
    <child link="hip0"/>
    <axis xyz="1 0 0"/>
    <origin xyz="0.2263 0.07 0"/>
    <limit effort="40" velocity="30" lower="-0.707" upper="0.707"/>
    <dynamics damping="0.0" friction="0.0"/>
    <!-- <dynamics damping="0.05" friction="0.160"/> -->
  </joint>

  <link name="upper0">
    <visual>
      <!-- <origin rpy="0 0 0" xyz="-${upperLegLength/2} ${-left*upperLegWidth} 0"/> -->
      <!-- <geometry>
					<box size="${upperLegLength} ${upperLegWidth} ${upperLegHeight}"/>
				</geometry> -->
      <!-- <material name="silver"/>
			</visual>
			<visual> -->
      <xacro:if value="1">
        <origin rpy="0 0  0" xyz="0 -0.02 0"/>
      </xacro:if>
      <xacro:if value="1">
        <origin rpy="3.14159265359 0  0" xyz="0 0.02 0"/>
      </xacro:if>
      <geometry>
        <mesh filename="meshes/Spirit40_Upper_leg_transformed.stl" scale="1 1 1"/>
      </geometry>
      <material name="darkgray"/>
    </visual>
    <collision>
      <origin rpy="0 0 0" xyz="-0.103 -0.022 0"/>
      <geometry>
        <box size="0.206 0.022 0.055"/>
      </geometry>
    </collision>
    <inertial>
      <mass value="0.775"/>
      <inertia ixx="5e-05" ixy="0" ixz="0" iyy="0.001" iyz="0" izz="0.001"/>
    </inertial>
  </link>

  <joint name="0" type="revolute">
    <parent link="hip0"/>
    <child link="upper0"/>
    <axis xyz="0 -1 0"/>
    <origin xyz="0.0 0.10098 0"/>
    <!--  rpy="0 -0.3 0" -->
    <limit effort="40" velocity="30" lower="-6.28318530718" upper="6.28318530718"/>
    <!--dynamics damping="0.05" friction="0.160"/-->
    <dynamics damping="0.0" friction="0.0"/>
    <!-- Originally, these were set to 0.0 and 0.0.  I'm trying to adjust them to see if I can get the robot to not jitter as much. -->
  </joint>

  <link name="lower0">
    <visual>
      <!-- <origin rpy="0 ${pi/2} 0" xyz="${lowerLegLength/2} 0 0"/> -->
      <!-- <geometry>
					<cylinder length="${lowerLegLength}" radius="${lowerLegRadius}"/>
				</geometry> -->
      <!-- <material name="darkgray"/>
			</visual>
			<visual> -->
      <xacro:if value="1">
        <origin rpy="0 0  0" xyz="0 0 0"/>
      </xacro:if>
      <xacro:if value="1">
        <origin rpy="3.14159265359 0  0" xyz="0 0 0"/>
      </xacro:if>
      <geometry>
        <mesh filename="meshes/Spirit40_Lower_Leg_transformed.stl" scale="1 1 1"/>
      </geometry>
      <material name="darkgray"/>
    </visual>
    <collision>
      <origin rpy="0 1.570796326795 0" xyz="0.103 0 0"/>
      <geometry>
        <cylinder length="0.206" radius="0.013"/>
      </geometry>
    </collision>
    <inertial>
      <mass value="0.075"/>
      <inertia ixx="5e-06" ixy="0" ixz="0" iyy="0.0001" iyz="0" izz="0.0001"/>
    </inertial>
  </link>

  <joint name="1" type="revolute">
    <parent link="upper0"/>
    <child link="lower0"/>
    <axis xyz="0 1 0"/>
    <origin xyz="-0.206 0 0"/>
    <!--rpy="0 0.5 0"-->
    <limit effort="40" velocity="30" lower="-3.14159265359" upper="3.14159265359"/>
    <!-- <dynamics damping="0.1" friction="1.05"/> -->
    <dynamics damping="0.0" friction="0.0"/>
    <!-- Originally, these were set to 0.0 and 0.0.  I'm trying to adjust them to see if I can get the robot to not spazz out as much. -->
  </joint>

  <link name="toe0">
    <contact>
      <friction_anchor/>
      <stiffness value="30000.0"/>
      <damping value="1000.0"/>
      <spinning_friction value="0.3"/>
      <lateral_friction value="50.0"/>
    </contact>
    <visual>
      <origin rpy="0 0 0" xyz="0 0 0"/>
      <geometry>
        <!--					<sphere radius="${toeRadius}"/>-->
        <sphere radius="0.001"/>
      </geometry>
      <material name="darkgray"/>
    </visual>
    <collision>
      <origin rpy="0 0 0" xyz="0 0 0"/>
      <geometry>
        <sphere radius="0.02"/>
      </geometry>
      <surface>
        <friction>
          <ode>
            <mu>100000</mu>
            <mu2>100000</mu2>
          </ode>
        </friction>
        <contact>
          <ode>
            <kp>30000.0</kp>
            <kd>1000.0</kd>
          </ode>
        </contact>
      </surface>
    </collision>
    <inertial>
      <mass value="0.015"/>
      <inertia ixx="0.000025" ixy="0" ixz="0" iyy="0.000025" iyz="0" izz="0.000025"/>
      <!-- <inertia ixx="2/5*${toeMass}*${toeRadius}*${toeRadius}"  ixy="0"  ixz="0" iyy="2/5*${toeMass}*${toeRadius}*${toeRadius}" iyz="0" izz="2/5*${toeMass}*${toeRadius}*${toeRadius}" /> -->
    </inertial>
  </link>

  <joint name="jtoe0" type="fixed">
    <parent link="lower0"/>
    <child link="toe0"/>
    <origin xyz="0.206 0 -0.0"/>
    <dynamics damping="0.0" friction="0.0"/>
  </joint>

  
  <link name="hip1">
    <visual>
      <!-- <origin rpy="${pi/2} 0 0" xyz="${front * 0} ${left * (dPodAxisToEdge)} 0"/> -->
      <!-- <geometry>
					<cylinder length="${podLength}" radius="${podRadius}"/>
				</geometry> -->
      <!-- <material name="${color}"/>
			</visual>
			<visual> -->
      <geometry>
        <mesh filename="meshes/Spirit40_Hip_Module_transformed.stl" scale="1 1 1"/>
      </geometry>
      <xacro:if value="-1">
        <origin rpy="0 0 0" xyz="0 0.0 0"/>
      </xacro:if>
      <xacro:if value="-1">
        <origin rpy="0 3.14159265359 0" xyz="0.0 0.0 0"/>
      </xacro:if>
      <xacro:if value="-1">
        <origin rpy="3.14159265359 0 0" xyz="0.0 0 0.0"/>
      </xacro:if>
      <xacro:if value="-1">
        <origin rpy="3.14159265359 3.14159265359 0" xyz="0.0 0.0 0.0"/>
      </xacro:if>
      <!-- <geometry>
					<mesh filename="file://$(arg mesh_dir)/Spirit40/Spirit40_Hip_Module_transformed.stl"
						  scale="1 1 1"/>
				</geometry> -->
      <material name="darkgray"/>
    </visual>
    <collision>
      <origin rpy="1.570796326795 0 0" xyz="0 0.028 0"/>
      <geometry>
        <cylinder length="0.08" radius="0.055"/>
      </geometry>
    </collision>
    <inertial>
      <mass value="0.575"/>
      <!-- <inertia ixx="1/12*${podMass}*${podLength}*${podLength} + 1/4*${podMass}*${podRadius}*${podRadius}"  ixy="0"  ixz="0" iyy="1/12*${podMass}*${podLength}*${podLength} + 1/4*${podMass}*${podRadius}*${podRadius}" iyz="0" izz="1/2*${podMass}*${podRadius}*$
				{podRadius}" /> -->
      <inertia ixx="0.00066963541" ixy="0" ixz="0" iyy="0.00066963541" iyz="0" izz="0.0008696875"/>
    </inertial>
  </link>

  <joint name="9" type="revolute">
    <parent link="body"/>
    <child link="hip1"/>
    <axis xyz="1 0 0"/>
    <origin xyz="-0.2263 0.07 0"/>
    <limit effort="40" velocity="30" lower="-0.707" upper="0.707"/>
    <dynamics damping="0.0" friction="0.0"/>
    <!-- <dynamics damping="0.05" friction="0.160"/> -->
  </joint>

  <link name="upper1">
    <visual>
      <!-- <origin rpy="0 0 0" xyz="-${upperLegLength/2} ${-left*upperLegWidth} 0"/> -->
      <!-- <geometry>
					<box size="${upperLegLength} ${upperLegWidth} ${upperLegHeight}"/>
				</geometry> -->
      <!-- <material name="silver"/>
			</visual>
			<visual> -->
      <xacro:if value="1">
        <origin rpy="0 0  0" xyz="0 -0.02 0"/>
      </xacro:if>
      <xacro:if value="1">
        <origin rpy="3.14159265359 0  0" xyz="0 0.02 0"/>
      </xacro:if>
      <geometry>
        <mesh filename="meshes/Spirit40_Upper_leg_transformed.stl" scale="1 1 1"/>
      </geometry>
      <material name="darkgray"/>
    </visual>
    <collision>
      <origin rpy="0 0 0" xyz="-0.103 -0.022 0"/>
      <geometry>
        <box size="0.206 0.022 0.055"/>
      </geometry>
    </collision>
    <inertial>
      <mass value="0.775"/>
      <inertia ixx="5e-05" ixy="0" ixz="0" iyy="0.001" iyz="0" izz="0.001"/>
    </inertial>
  </link>

  <joint name="2" type="revolute">
    <parent link="hip1"/>
    <child link="upper1"/>
    <axis xyz="0 -1 0"/>
    <origin xyz="-0.0 0.10098 0"/>
    <!--  rpy="0 -0.3 0" -->
    <limit effort="40" velocity="30" lower="-6.28318530718" upper="6.28318530718"/>
    <!--dynamics damping="0.05" friction="0.160"/-->
    <dynamics damping="0.0" friction="0.0"/>
    <!-- Originally, these were set to 0.0 and 0.0.  I'm trying to adjust them to see if I can get the robot to not jitter as much. -->
  </joint>

  <link name="lower1">
    <visual>
      <!-- <origin rpy="0 ${pi/2} 0" xyz="${lowerLegLength/2} 0 0"/> -->
      <!-- <geometry>
					<cylinder length="${lowerLegLength}" radius="${lowerLegRadius}"/>
				</geometry> -->
      <!-- <material name="darkgray"/>
			</visual>
			<visual> -->
      <xacro:if value="1">
        <origin rpy="0 0  0" xyz="0 0 0"/>
      </xacro:if>
      <xacro:if value="1">
        <origin rpy="3.14159265359 0  0" xyz="0 0 0"/>
      </xacro:if>
      <geometry>
        <mesh filename="meshes/Spirit40_Lower_Leg_transformed.stl" scale="1 1 1"/>
      </geometry>
      <material name="darkgray"/>
    </visual>
    <collision>
      <origin rpy="0 1.570796326795 0" xyz="0.103 0 0"/>
      <geometry>
        <cylinder length="0.206" radius="0.013"/>
      </geometry>
    </collision>
    <inertial>
      <mass value="0.075"/>
      <inertia ixx="5e-06" ixy="0" ixz="0" iyy="0.0001" iyz="0" izz="0.0001"/>
    </inertial>
  </link>

  <joint name="3" type="revolute">
    <parent link="upper1"/>
    <child link="lower1"/>
    <axis xyz="0 1 0"/>
    <origin xyz="-0.206 0 0"/>
    <!--rpy="0 0.5 0"-->
    <limit effort="40" velocity="30" lower="-3.14159265359" upper="3.14159265359"/>
    <!-- <dynamics damping="0.1" friction="1.05"/> -->
    <dynamics damping="0.0" friction="0.0"/>
    <!-- Originally, these were set to 0.0 and 0.0.  I'm trying to adjust them to see if I can get the robot to not spazz out as much. -->
  </joint>

  <link name="toe1">
    <contact>
      <friction_anchor/>
      <stiffness value="30000.0"/>
      <damping value="1000.0"/>
      <spinning_friction value="0.3"/>
      <lateral_friction value="50.0"/>
    </contact>
    <visual>
      <origin rpy="0 0 0" xyz="0 0 0"/>
      <geometry>
        <!--					<sphere radius="${toeRadius}"/>-->
        <sphere radius="0.001"/>
      </geometry>
      <material name="darkgray"/>
    </visual>
    <collision>
      <origin rpy="0 0 0" xyz="0 0 0"/>
      <geometry>
        <sphere radius="0.02"/>
      </geometry>
      <surface>
        <friction>
          <ode>
            <mu>100000</mu>
            <mu2>100000</mu2>
          </ode>
        </friction>
        <contact>
          <ode>
            <kp>30000.0</kp>
            <kd>1000.0</kd>
          </ode>
        </contact>
      </surface>
    </collision>
    <inertial>
      <mass value="0.015"/>
      <inertia ixx="0.000025" ixy="0" ixz="0" iyy="0.000025" iyz="0" izz="0.000025"/>
      <!-- <inertia ixx="2/5*${toeMass}*${toeRadius}*${toeRadius}"  ixy="0"  ixz="0" iyy="2/5*${toeMass}*${toeRadius}*${toeRadius}" iyz="0" izz="2/5*${toeMass}*${toeRadius}*${toeRadius}" /> -->
    </inertial>
  </link>

  <joint name="jtoe1" type="fixed">
    <parent link="lower1"/>
    <child link="toe1"/>
    <origin xyz="0.206 0 -0.0"/>
    <dynamics damping="0.0" friction="0.0"/>
  </joint>
  <link name="hip2">
    <visual>
      <!-- <origin rpy="${pi/2} 0 0" xyz="${front * 0} ${left * (dPodAxisToEdge)} 0"/> -->
      <!-- <geometry>
					<cylinder length="${podLength}" radius="${podRadius}"/>
				</geometry> -->
      <!-- <material name="${color}"/>
			</visual>
			<visual> -->
      <geometry>
        <mesh filename="meshes/Spirit40_Hip_Module_transformed.stl" scale="1 1 1"/>
      </geometry>
      <xacro:if value="1">
        <origin rpy="0 0 0" xyz="0 0.0 0"/>
      </xacro:if>
      <xacro:if value="1">
        <origin rpy="0 3.14159265359 0" xyz="0.0 0.0 0"/>
      </xacro:if>
      <xacro:if value="1">
        <origin rpy="3.14159265359 0 0" xyz="0.0 0 0.0"/>
      </xacro:if>
      <xacro:if value="1">
        <origin rpy="3.14159265359 3.14159265359 0" xyz="0.0 0.0 0.0"/>
      </xacro:if>
      <!-- <geometry>
					<mesh filename="file://$(arg mesh_dir)/Spirit40/Spirit40_Hip_Module_transformed.stl"
						  scale="1 1 1"/>
				</geometry> -->
      <material name="darkgray"/>
    </visual>
    <collision>
      <origin rpy="1.570796326795 0 0" xyz="0 -0.028 0"/>
      <geometry>
        <cylinder length="0.08" radius="0.055"/>
      </geometry>
    </collision>
    <inertial>
      <mass value="0.575"/>
      <!-- <inertia ixx="1/12*${podMass}*${podLength}*${podLength} + 1/4*${podMass}*${podRadius}*${podRadius}"  ixy="0"  ixz="0" iyy="1/12*${podMass}*${podLength}*${podLength} + 1/4*${podMass}*${podRadius}*${podRadius}" iyz="0" izz="1/2*${podMass}*${podRadius}*$
				{podRadius}" /> -->
      <inertia ixx="0.00066963541" ixy="0" ixz="0" iyy="0.00066963541" iyz="0" izz="0.0008696875"/>
    </inertial>
  </link>

  <joint name="10" type="revolute">
    <parent link="body"/>
    <child link="hip2"/>
    <axis xyz="1 0 0"/>
    <origin xyz="0.2263 -0.07 0"/>
    <limit effort="40" velocity="30" lower="-0.707" upper="0.707"/>
    <dynamics damping="0.0" friction="0.0"/>
    <!-- <dynamics damping="0.05" friction="0.160"/> -->
  </joint>


  <link name="upper2">
    <visual>
      <!-- <origin rpy="0 0 0" xyz="-${upperLegLength/2} ${-left*upperLegWidth} 0"/> -->
      <!-- <geometry>
					<box size="${upperLegLength} ${upperLegWidth} ${upperLegHeight}"/>
				</geometry> -->
      <!-- <material name="silver"/>
			</visual>
			<visual> -->
      <xacro:if value="-1">
        <origin rpy="0 0  0" xyz="0 -0.02 0"/>
      </xacro:if>
      <xacro:if value="-1">
        <origin rpy="3.14159265359 0  0" xyz="0 0.02 0"/>
      </xacro:if>
      <geometry>
        <mesh filename="meshes/Spirit40_Upper_leg_transformed.stl" scale="1 1 1"/>
      </geometry>
      <material name="darkgray"/>
    </visual>
    <collision>
      <origin rpy="0 0 0" xyz="-0.103 0.022 0"/>
      <geometry>
        <box size="0.206 0.022 0.055"/>
      </geometry>
    </collision>
    <inertial>
      <mass value="0.775"/>
      <inertia ixx="5e-05" ixy="0" ixz="0" iyy="0.001" iyz="0" izz="0.001"/>
    </inertial>
  </link>
 
  <joint name="4" type="revolute">
    <parent link="hip2"/>
    <child link="upper2"/>
    <axis xyz="0 -1 0"/>
    <origin xyz="0.0 -0.10098 0"/>
    <!--  rpy="0 -0.3 0" -->
    <limit effort="40" velocity="30" lower="-6.28318530718" upper="6.28318530718"/>
    <!--dynamics damping="0.05" friction="0.160"/-->
    <dynamics damping="0.0" friction="0.0"/>
    <!-- Originally, these were set to 0.0 and 0.0.  I'm trying to adjust them to see if I can get the robot to not jitter as much. -->
  </joint>

  <link name="lower2">
    <visual>
      <!-- <origin rpy="0 ${pi/2} 0" xyz="${lowerLegLength/2} 0 0"/> -->
      <!-- <geometry>
					<cylinder length="${lowerLegLength}" radius="${lowerLegRadius}"/>
				</geometry> -->
      <!-- <material name="darkgray"/>
			</visual>
			<visual> -->
      <xacro:if value="-1">
        <origin rpy="0 0  0" xyz="0 0 0"/>
      </xacro:if>
      <xacro:if value="-1">
        <origin rpy="3.14159265359 0  0" xyz="0 0 0"/>
      </xacro:if>
      <geometry>
        <mesh filename="meshes/Spirit40_Lower_Leg_transformed.stl" scale="1 1 1"/>
      </geometry>
      <material name="darkgray"/>
    </visual>
    <collision>
      <origin rpy="0 1.570796326795 0" xyz="0.103 0 0"/>
      <geometry>
        <cylinder length="0.206" radius="0.013"/>
      </geometry>
    </collision>
    <inertial>
      <mass value="0.075"/>
      <inertia ixx="5e-06" ixy="0" ixz="0" iyy="0.0001" iyz="0" izz="0.0001"/>
    </inertial>
  </link>

  <joint name="5" type="revolute">
    <parent link="upper2"/>
    <child link="lower2"/>
    <axis xyz="0 1 0"/>
    <origin xyz="-0.206 0 0"/>
    <!--rpy="0 0.5 0"-->
    <limit effort="40" velocity="30" lower="-3.14159265359" upper="3.14159265359"/>
    <!-- <dynamics damping="0.1" friction="1.05"/> -->
    <dynamics damping="0.0" friction="0.0"/>
    <!-- Originally, these were set to 0.0 and 0.0.  I'm trying to adjust them to see if I can get the robot to not spazz out as much. -->
  </joint>

  <link name="toe2">
    <contact>
      <friction_anchor/>
      <stiffness value="30000.0"/>
      <damping value="1000.0"/>
      <spinning_friction value="0.3"/>
      <lateral_friction value="50.0"/>
    </contact>
    <visual>
      <origin rpy="0 0 0" xyz="0 0 0"/>
      <geometry>
        <!--					<sphere radius="${toeRadius}"/>-->
        <sphere radius="0.001"/>
      </geometry>
      <material name="darkgray"/>
    </visual>
    <collision>
      <origin rpy="0 0 0" xyz="0 0 0"/>
      <geometry>
        <sphere radius="0.02"/>
      </geometry>
      <surface>
        <friction>
          <ode>
            <mu>100000</mu>
            <mu2>100000</mu2>
          </ode>
        </friction>
        <contact>
          <ode>
            <kp>30000.0</kp>
            <kd>1000.0</kd>
          </ode>
        </contact>
      </surface>
    </collision>
    <inertial>
      <mass value="0.015"/>
      <inertia ixx="0.000025" ixy="0" ixz="0" iyy="0.000025" iyz="0" izz="0.000025"/>
      <!-- <inertia ixx="2/5*${toeMass}*${toeRadius}*${toeRadius}"  ixy="0"  ixz="0" iyy="2/5*${toeMass}*${toeRadius}*${toeRadius}" iyz="0" izz="2/5*${toeMass}*${toeRadius}*${toeRadius}" /> -->
    </inertial>
  </link>

  <joint name="jtoe2" type="fixed">
    <parent link="lower2"/>
    <child link="toe2"/>
    <origin xyz="0.206 0 -0.0"/>
    <dynamics damping="0.0" friction="0.0"/>
  </joint>
  <link name="hip3">
    <visual>
      <!-- <origin rpy="${pi/2} 0 0" xyz="${front * 0} ${left * (dPodAxisToEdge)} 0"/> -->
      <!-- <geometry>
					<cylinder length="${podLength}" radius="${podRadius}"/>
				</geometry> -->
      <!-- <material name="${color}"/>
			</visual>
			<visual> -->
      <geometry>
        <mesh filename="meshes/Spirit40_Hip_Module_transformed.stl" scale="1 1 1"/>
      </geometry>
      <xacro:if value="-1">
        <origin rpy="0 0 0" xyz="0 0.0 0"/>
      </xacro:if>
      <xacro:if value="-1">
        <origin rpy="0 3.14159265359 0" xyz="0.0 0.0 0"/>
      </xacro:if>
      <xacro:if value="-1">
        <origin rpy="3.14159265359 0 0" xyz="0.0 0 0.0"/>
      </xacro:if>
      <xacro:if value="-1">
        <origin rpy="3.14159265359 3.14159265359 0" xyz="0.0 0.0 0.0"/>
      </xacro:if>
      <!-- <geometry>
					<mesh filename="file://$(arg mesh_dir)/Spirit40/Spirit40_Hip_Module_transformed.stl"
						  scale="1 1 1"/>
				</geometry> -->
      <material name="darkgray"/>
    </visual>
    <collision>
      <origin rpy="1.570796326795 0 0" xyz="0 -0.028 0"/>
      <geometry>
        <cylinder length="0.08" radius="0.055"/>
      </geometry>
    </collision>
    <inertial>
      <mass value="0.575"/>
      <!-- <inertia ixx="1/12*${podMass}*${podLength}*${podLength} + 1/4*${podMass}*${podRadius}*${podRadius}"  ixy="0"  ixz="0" iyy="1/12*${podMass}*${podLength}*${podLength} + 1/4*${podMass}*${podRadius}*${podRadius}" iyz="0" izz="1/2*${podMass}*${podRadius}*$
				{podRadius}" /> -->
      <inertia ixx="0.00066963541" ixy="0" ixz="0" iyy="0.00066963541" iyz="0" izz="0.0008696875"/>
    </inertial>
  </link>

  <joint name="11" type="revolute">
    <parent link="body"/>
    <child link="hip3"/>
    <axis xyz="1 0 0"/>
    <origin xyz="-0.2263 -0.07 0"/>
    <limit effort="40" velocity="30" lower="-0.707" upper="0.707"/>
    <dynamics damping="0.0" friction="0.0"/>
    <!-- <dynamics damping="0.05" friction="0.160"/> -->
  </joint>

  <link name="upper3">
    <visual>
      <!-- <origin rpy="0 0 0" xyz="-${upperLegLength/2} ${-left*upperLegWidth} 0"/> -->
      <!-- <geometry>
					<box size="${upperLegLength} ${upperLegWidth} ${upperLegHeight}"/>
				</geometry> -->
      <!-- <material name="silver"/>
			</visual>
			<visual> -->
      <xacro:if value="-1">
        <origin rpy="0 0  0" xyz="0 -0.02 0"/>
      </xacro:if>
      <xacro:if value="-1">
        <origin rpy="3.14159265359 0  0" xyz="0 0.02 0"/>
      </xacro:if>
      <geometry>
        <mesh filename="meshes/Spirit40_Upper_leg_transformed.stl" scale="1 1 1"/>
      </geometry>
      <material name="darkgray"/>
    </visual>
    <collision>
      <origin rpy="0 0 0" xyz="-0.103 0.022 0"/>
      <geometry>
        <box size="0.206 0.022 0.055"/>
      </geometry>
    </collision>
    <inertial>
      <mass value="0.775"/>
      <inertia ixx="5e-05" ixy="0" ixz="0" iyy="0.001" iyz="0" izz="0.001"/>
    </inertial>
  </link>

  <joint name="6" type="revolute">
    <parent link="hip3"/>
    <child link="upper3"/>
    <axis xyz="0 -1 0"/>
    <origin xyz="-0.0 -0.10098 0"/>
    <!--  rpy="0 -0.3 0" -->
    <limit effort="40" velocity="30" lower="-6.28318530718" upper="6.28318530718"/>
    <!--dynamics damping="0.05" friction="0.160"/-->
    <dynamics damping="0.0" friction="0.0"/>
    <!-- Originally, these were set to 0.0 and 0.0.  I'm trying to adjust them to see if I can get the robot to not jitter as much. -->
  </joint>

  <link name="lower3">
    <visual>
      <!-- <origin rpy="0 ${pi/2} 0" xyz="${lowerLegLength/2} 0 0"/> -->
      <!-- <geometry>
					<cylinder length="${lowerLegLength}" radius="${lowerLegRadius}"/>
				</geometry> -->
      <!-- <material name="darkgray"/>
			</visual>
			<visual> -->
      <xacro:if value="-1">
        <origin rpy="0 0  0" xyz="0 0 0"/>
      </xacro:if>
      <xacro:if value="-1">
        <origin rpy="3.14159265359 0  0" xyz="0 0 0"/>
      </xacro:if>
      <geometry>
        <mesh filename="meshes/Spirit40_Lower_Leg_transformed.stl" scale="1 1 1"/>
      </geometry>
      <material name="darkgray"/>
    </visual>
    <collision>
      <origin rpy="0 1.570796326795 0" xyz="0.103 0 0"/>
      <geometry>
        <cylinder length="0.206" radius="0.013"/>
      </geometry>
    </collision>
    <inertial>
      <mass value="0.075"/>
      <inertia ixx="5e-06" ixy="0" ixz="0" iyy="0.0001" iyz="0" izz="0.0001"/>
    </inertial>
  </link>

  <joint name="7" type="revolute">
    <parent link="upper3"/>
    <child link="lower3"/>
    <axis xyz="0 1 0"/>
    <origin xyz="-0.206 0 0"/>
    <!--rpy="0 0.5 0"-->
    <limit effort="40" velocity="30" lower="-3.14159265359" upper="3.14159265359"/>
    <!-- <dynamics damping="0.1" friction="1.05"/> -->
    <dynamics damping="0.0" friction="0.0"/>
    <!-- Originally, these were set to 0.0 and 0.0.  I'm trying to adjust them to see if I can get the robot to not spazz out as much. -->
  </joint>

  <link name="toe3">
    <contact>
      <friction_anchor/>
      <stiffness value="30000.0"/>
      <damping value="1000.0"/>
      <spinning_friction value="0.3"/>
      <lateral_friction value="50.0"/>
    </contact>
    <visual>
      <origin rpy="0 0 0" xyz="0 0 0"/>
      <geometry>
        <!--					<sphere radius="${toeRadius}"/>-->
        <sphere radius="0.001"/>
      </geometry>
      <material name="darkgray"/>
    </visual>
    <collision>
      <origin rpy="0 0 0" xyz="0 0 0"/>
      <geometry>
        <sphere radius="0.02"/>
      </geometry>
      <surface>
        <friction>
          <ode>
            <mu>100000</mu>
            <mu2>100000</mu2>
          </ode>
        </friction>
        <contact>
          <ode>
            <kp>30000.0</kp>
            <kd>1000.0</kd>
          </ode>
        </contact>
      </surface>
    </collision>
    <inertial>
      <mass value="0.015"/>
      <inertia ixx="0.000025" ixy="0" ixz="0" iyy="0.000025" iyz="0" izz="0.000025"/>
      <!-- <inertia ixx="2/5*${toeMass}*${toeRadius}*${toeRadius}"  ixy="0"  ixz="0" iyy="2/5*${toeMass}*${toeRadius}*${toeRadius}" iyz="0" izz="2/5*${toeMass}*${toeRadius}*${toeRadius}" /> -->
    </inertial>
  </link>

  <joint name="jtoe3" type="fixed">
    <parent link="lower3"/>
    <child link="toe3"/>
    <origin xyz="0.206 0 -0.0"/>
    <dynamics damping="0.0" friction="0.0"/>
  </joint>



</robot>
